
  You can now view your Streamlit app in your browser.

  URL: http://localhost:8501

  For better performance, install the Watchdog module:

  $ xcode-select --install
  $ pip install watchdog
            
2025-07-28 21:50:21.121 Uncaught app execution
Traceback (most recent call last):
  File "/Users/dedykurniawan/Documents/BI & Analitics/bi/lib/python3.13/site-packages/urllib3/connection.py", line 198, in _new_conn
    sock = connection.create_connection(
        (self._dns_host, self.port),
    ...<2 lines>...
        socket_options=self.socket_options,
    )
  File "/Users/dedykurniawan/Documents/BI & Analitics/bi/lib/python3.13/site-packages/urllib3/util/connection.py", line 85, in create_connection
    raise err
  File "/Users/dedykurniawan/Documents/BI & Analitics/bi/lib/python3.13/site-packages/urllib3/util/connection.py", line 73, in create_connection
    sock.connect(sa)
    ~~~~~~~~~~~~^^^^
ConnectionRefusedError: [Errno 61] Connection refused

The above exception was the direct cause of the following exception:

Traceback (most recent call last):
  File "/Users/dedykurniawan/Documents/BI & Analitics/bi/lib/python3.13/site-packages/urllib3/connectionpool.py", line 787, in urlopen
    response = self._make_request(
        conn,
    ...<10 lines>...
        **response_kw,
    )
  File "/Users/dedykurniawan/Documents/BI & Analitics/bi/lib/python3.13/site-packages/urllib3/connectionpool.py", line 493, in _make_request
    conn.request(
    ~~~~~~~~~~~~^
        method,
        ^^^^^^^
    ...<6 lines>...
        enforce_content_length=enforce_content_length,
        ^^^^^^^^^^^^^^^^^^^^^^^^^^^^^^^^^^^^^^^^^^^^^^
    )
    ^
  File "/Users/dedykurniawan/Documents/BI & Analitics/bi/lib/python3.13/site-packages/urllib3/connection.py", line 494, in request
    self.endheaders()
    ~~~~~~~~~~~~~~~^^
  File "/opt/homebrew/Cellar/python@3.13/3.13.5/Frameworks/Python.framework/Versions/3.13/lib/python3.13/http/client.py", line 1333, in endheaders
    self._send_output(message_body, encode_chunked=encode_chunked)
    ~~~~~~~~~~~~~~~~~^^^^^^^^^^^^^^^^^^^^^^^^^^^^^^^^^^^^^^^^^^^^^
  File "/opt/homebrew/Cellar/python@3.13/3.13.5/Frameworks/Python.framework/Versions/3.13/lib/python3.13/http/client.py", line 1093, in _send_output
    self.send(msg)
    ~~~~~~~~~^^^^^
  File "/opt/homebrew/Cellar/python@3.13/3.13.5/Frameworks/Python.framework/Versions/3.13/lib/python3.13/http/client.py", line 1037, in send
    self.connect()
    ~~~~~~~~~~~~^^
  File "/Users/dedykurniawan/Documents/BI & Analitics/bi/lib/python3.13/site-packages/urllib3/connection.py", line 325, in connect
    self.sock = self._new_conn()
                ~~~~~~~~~~~~~~^^
  File "/Users/dedykurniawan/Documents/BI & Analitics/bi/lib/python3.13/site-packages/urllib3/connection.py", line 213, in _new_conn
    raise NewConnectionError(
        self, f"Failed to establish a new connection: {e}"
    ) from e
urllib3.exceptions.NewConnectionError: <urllib3.connection.HTTPConnection object at 0x103a17240>: Failed to establish a new connection: [Errno 61] Connection refused

The above exception was the direct cause of the following exception:

Traceback (most recent call last):
  File "/Users/dedykurniawan/Documents/BI & Analitics/bi/lib/python3.13/site-packages/requests/adapters.py", line 486, in send
    resp = conn.urlopen(
        method=request.method,
    ...<9 lines>...
        chunked=chunked,
    )
  File "/Users/dedykurniawan/Documents/BI & Analitics/bi/lib/python3.13/site-packages/urllib3/connectionpool.py", line 841, in urlopen
    retries = retries.increment(
        method, url, error=new_e, _pool=self, _stacktrace=sys.exc_info()[2]
    )
  File "/Users/dedykurniawan/Documents/BI & Analitics/bi/lib/python3.13/site-packages/urllib3/util/retry.py", line 519, in increment
    raise MaxRetryError(_pool, url, reason) from reason  # type: ignore[arg-type]
    ^^^^^^^^^^^^^^^^^^^^^^^^^^^^^^^^^^^^^^^^^^^^^^^^^^^
urllib3.exceptions.MaxRetryError: HTTPConnectionPool(host='localhost', port=5001): Max retries exceeded with url: /health (Caused by NewConnectionError('<urllib3.connection.HTTPConnection object at 0x103a17240>: Failed to establish a new connection: [Errno 61] Connection refused'))

During handling of the above exception, another exception occurred:

Traceback (most recent call last):
  File "/Users/dedykurniawan/Documents/BI & Analitics/bi/lib/python3.13/site-packages/streamlit/runtime/scriptrunner/exec_code.py", line 128, in exec_func_with_error_handling
    result = func()
  File "/Users/dedykurniawan/Documents/BI & Analitics/bi/lib/python3.13/site-packages/streamlit/runtime/scriptrunner/script_runner.py", line 669, in code_to_exec
    exec(code, module.__dict__)  # noqa: S102
    ~~~~^^^^^^^^^^^^^^^^^^^^^^^
  File "/Users/dedykurniawan/Documents/BI & Analitics/FE/streamlit_fe.py", line 162, in <module>
    api_status = "ðŸŸ¢ Connected" if requests.get(f"{API_BASE_URL}/health", timeout=5).status_code == 200 else "ðŸ”´ Disconnected"
                                   ~~~~~~~~~~~~^^^^^^^^^^^^^^^^^^^^^^^^^^^^^^^^^^^^^
  File "/Users/dedykurniawan/Documents/BI & Analitics/bi/lib/python3.13/site-packages/requests/api.py", line 73, in get
    return request("get", url, params=params, **kwargs)
  File "/Users/dedykurniawan/Documents/BI & Analitics/bi/lib/python3.13/site-packages/requests/api.py", line 59, in request
    return session.request(method=method, url=url, **kwargs)
           ~~~~~~~~~~~~~~~^^^^^^^^^^^^^^^^^^^^^^^^^^^^^^^^^^
  File "/Users/dedykurniawan/Documents/BI & Analitics/bi/lib/python3.13/site-packages/requests/sessions.py", line 589, in request
    resp = self.send(prep, **send_kwargs)
  File "/Users/dedykurniawan/Documents/BI & Analitics/bi/lib/python3.13/site-packages/requests/sessions.py", line 703, in send
    r = adapter.send(request, **kwargs)
  File "/Users/dedykurniawan/Documents/BI & Analitics/bi/lib/python3.13/site-packages/requests/adapters.py", line 519, in send
    raise ConnectionError(e, request=request)
requests.exceptions.ConnectionError: HTTPConnectionPool(host='localhost', port=5001): Max retries exceeded with url: /health (Caused by NewConnectionError('<urllib3.connection.HTTPConnection object at 0x103a17240>: Failed to establish a new connection: [Errno 61] Connection refused'))
2025-07-28 21:50:24.485 Uncaught app execution
Traceback (most recent call last):
  File "/Users/dedykurniawan/Documents/BI & Analitics/bi/lib/python3.13/site-packages/urllib3/connection.py", line 198, in _new_conn
    sock = connection.create_connection(
        (self._dns_host, self.port),
    ...<2 lines>...
        socket_options=self.socket_options,
    )
  File "/Users/dedykurniawan/Documents/BI & Analitics/bi/lib/python3.13/site-packages/urllib3/util/connection.py", line 85, in create_connection
    raise err
  File "/Users/dedykurniawan/Documents/BI & Analitics/bi/lib/python3.13/site-packages/urllib3/util/connection.py", line 73, in create_connection
    sock.connect(sa)
    ~~~~~~~~~~~~^^^^
ConnectionRefusedError: [Errno 61] Connection refused

The above exception was the direct cause of the following exception:

Traceback (most recent call last):
  File "/Users/dedykurniawan/Documents/BI & Analitics/bi/lib/python3.13/site-packages/urllib3/connectionpool.py", line 787, in urlopen
    response = self._make_request(
        conn,
    ...<10 lines>...
        **response_kw,
    )
  File "/Users/dedykurniawan/Documents/BI & Analitics/bi/lib/python3.13/site-packages/urllib3/connectionpool.py", line 493, in _make_request
    conn.request(
    ~~~~~~~~~~~~^
        method,
        ^^^^^^^
    ...<6 lines>...
        enforce_content_length=enforce_content_length,
        ^^^^^^^^^^^^^^^^^^^^^^^^^^^^^^^^^^^^^^^^^^^^^^
    )
    ^
  File "/Users/dedykurniawan/Documents/BI & Analitics/bi/lib/python3.13/site-packages/urllib3/connection.py", line 494, in request
    self.endheaders()
    ~~~~~~~~~~~~~~~^^
  File "/opt/homebrew/Cellar/python@3.13/3.13.5/Frameworks/Python.framework/Versions/3.13/lib/python3.13/http/client.py", line 1333, in endheaders
    self._send_output(message_body, encode_chunked=encode_chunked)
    ~~~~~~~~~~~~~~~~~^^^^^^^^^^^^^^^^^^^^^^^^^^^^^^^^^^^^^^^^^^^^^
  File "/opt/homebrew/Cellar/python@3.13/3.13.5/Frameworks/Python.framework/Versions/3.13/lib/python3.13/http/client.py", line 1093, in _send_output
    self.send(msg)
    ~~~~~~~~~^^^^^
  File "/opt/homebrew/Cellar/python@3.13/3.13.5/Frameworks/Python.framework/Versions/3.13/lib/python3.13/http/client.py", line 1037, in send
    self.connect()
    ~~~~~~~~~~~~^^
  File "/Users/dedykurniawan/Documents/BI & Analitics/bi/lib/python3.13/site-packages/urllib3/connection.py", line 325, in connect
    self.sock = self._new_conn()
                ~~~~~~~~~~~~~~^^
  File "/Users/dedykurniawan/Documents/BI & Analitics/bi/lib/python3.13/site-packages/urllib3/connection.py", line 213, in _new_conn
    raise NewConnectionError(
        self, f"Failed to establish a new connection: {e}"
    ) from e
urllib3.exceptions.NewConnectionError: <urllib3.connection.HTTPConnection object at 0x12e7e7460>: Failed to establish a new connection: [Errno 61] Connection refused

The above exception was the direct cause of the following exception:

Traceback (most recent call last):
  File "/Users/dedykurniawan/Documents/BI & Analitics/bi/lib/python3.13/site-packages/requests/adapters.py", line 486, in send
    resp = conn.urlopen(
        method=request.method,
    ...<9 lines>...
        chunked=chunked,
    )
  File "/Users/dedykurniawan/Documents/BI & Analitics/bi/lib/python3.13/site-packages/urllib3/connectionpool.py", line 841, in urlopen
    retries = retries.increment(
        method, url, error=new_e, _pool=self, _stacktrace=sys.exc_info()[2]
    )
  File "/Users/dedykurniawan/Documents/BI & Analitics/bi/lib/python3.13/site-packages/urllib3/util/retry.py", line 519, in increment
    raise MaxRetryError(_pool, url, reason) from reason  # type: ignore[arg-type]
    ^^^^^^^^^^^^^^^^^^^^^^^^^^^^^^^^^^^^^^^^^^^^^^^^^^^
urllib3.exceptions.MaxRetryError: HTTPConnectionPool(host='localhost', port=5001): Max retries exceeded with url: /health (Caused by NewConnectionError('<urllib3.connection.HTTPConnection object at 0x12e7e7460>: Failed to establish a new connection: [Errno 61] Connection refused'))

During handling of the above exception, another exception occurred:

Traceback (most recent call last):
  File "/Users/dedykurniawan/Documents/BI & Analitics/bi/lib/python3.13/site-packages/streamlit/runtime/scriptrunner/exec_code.py", line 128, in exec_func_with_error_handling
    result = func()
  File "/Users/dedykurniawan/Documents/BI & Analitics/bi/lib/python3.13/site-packages/streamlit/runtime/scriptrunner/script_runner.py", line 669, in code_to_exec
    exec(code, module.__dict__)  # noqa: S102
    ~~~~^^^^^^^^^^^^^^^^^^^^^^^
  File "/Users/dedykurniawan/Documents/BI & Analitics/FE/streamlit_fe.py", line 162, in <module>
    api_status = "ðŸŸ¢ Connected" if requests.get(f"{API_BASE_URL}/health", timeout=5).status_code == 200 else "ðŸ”´ Disconnected"
                                   ~~~~~~~~~~~~^^^^^^^^^^^^^^^^^^^^^^^^^^^^^^^^^^^^^
  File "/Users/dedykurniawan/Documents/BI & Analitics/bi/lib/python3.13/site-packages/requests/api.py", line 73, in get
    return request("get", url, params=params, **kwargs)
  File "/Users/dedykurniawan/Documents/BI & Analitics/bi/lib/python3.13/site-packages/requests/api.py", line 59, in request
    return session.request(method=method, url=url, **kwargs)
           ~~~~~~~~~~~~~~~^^^^^^^^^^^^^^^^^^^^^^^^^^^^^^^^^^
  File "/Users/dedykurniawan/Documents/BI & Analitics/bi/lib/python3.13/site-packages/requests/sessions.py", line 589, in request
    resp = self.send(prep, **send_kwargs)
  File "/Users/dedykurniawan/Documents/BI & Analitics/bi/lib/python3.13/site-packages/requests/sessions.py", line 703, in send
    r = adapter.send(request, **kwargs)
  File "/Users/dedykurniawan/Documents/BI & Analitics/bi/lib/python3.13/site-packages/requests/adapters.py", line 519, in send
    raise ConnectionError(e, request=request)
requests.exceptions.ConnectionError: HTTPConnectionPool(host='localhost', port=5001): Max retries exceeded with url: /health (Caused by NewConnectionError('<urllib3.connection.HTTPConnection object at 0x12e7e7460>: Failed to establish a new connection: [Errno 61] Connection refused'))
  Stopping...
